{
    DataVersion: 3955,
    size: [5, 4, 5],
    data: [
        {pos: [0, 0, 0], state: "anvilcraft:crushing_table{waterlogged:false}"},
        {pos: [0, 0, 2], state: "anvilcraft:transparent_crafting_table{type:corner_nw}"},
        {pos: [0, 0, 3], state: "anvilcraft:transparent_crafting_table{type:side_w}"},
        {pos: [0, 0, 4], state: "anvilcraft:transparent_crafting_table{type:corner_sw}"},
        {pos: [1, 0, 0], state: "minecraft:cauldron"},
        {pos: [1, 0, 2], state: "anvilcraft:transparent_crafting_table{type:side_n}"},
        {pos: [1, 0, 3], state: "anvilcraft:transparent_crafting_table{type:center}"},
        {pos: [1, 0, 4], state: "anvilcraft:transparent_crafting_table{type:side_s}"},
        {pos: [2, 0, 0], state: "anvilcraft:block_placer{orientation:south_up,triggered:false}"},
        {pos: [2, 0, 2], state: "anvilcraft:transparent_crafting_table{type:corner_ne}"},
        {pos: [2, 0, 3], state: "anvilcraft:transparent_crafting_table{type:side_e}"},
        {pos: [2, 0, 4], state: "anvilcraft:transparent_crafting_table{type:corner_se}"},
        {pos: [3, 0, 0], state: "anvilcraft:stamping_platform{facing:south,waterlogged:false}"},
        {pos: [4, 0, 0], state: "anvilcraft:item_collector{overload:false,powered:false}", nbt: {Cooldown: 0, Inventory: {FilterEnabled: 0b, Inventory: [{Disabled: 0b, IsEmptySlot: 1b, Slot: 0, SlotFilterEnabled: 0b}, {Disabled: 0b, IsEmptySlot: 1b, Slot: 1, SlotFilterEnabled: 0b}, {Disabled: 0b, IsEmptySlot: 1b, Slot: 2, SlotFilterEnabled: 0b}, {Disabled: 0b, IsEmptySlot: 1b, Slot: 3, SlotFilterEnabled: 0b}, {Disabled: 0b, IsEmptySlot: 1b, Slot: 4, SlotFilterEnabled: 0b}, {Disabled: 0b, IsEmptySlot: 1b, Slot: 5, SlotFilterEnabled: 0b}, {Disabled: 0b, IsEmptySlot: 1b, Slot: 6, SlotFilterEnabled: 0b}, {Disabled: 0b, IsEmptySlot: 1b, Slot: 7, SlotFilterEnabled: 0b}, {Disabled: 0b, IsEmptySlot: 1b, Slot: 8, SlotFilterEnabled: 0b}], Size: 9}, RangeRadius: 0, cd: 2, id: "anvilcraft:item_collector"}},
        {pos: [4, 0, 1], state: "anvilcraft:creative_generator", nbt: {id: "anvilcraft:creative_generator", power: 8192}},
        {pos: [4, 0, 2], state: "anvilcraft:batch_crafter{facing:west,overload:false,powered:false}", nbt: {Cooldown: 0, HasDisplayItemStack: 0b, Inventory: {FilterEnabled: 0b, Inventory: [{Disabled: 0b, IsEmptySlot: 1b, Slot: 0, SlotFilterEnabled: 0b}, {Disabled: 0b, IsEmptySlot: 1b, Slot: 1, SlotFilterEnabled: 0b}, {Disabled: 0b, IsEmptySlot: 1b, Slot: 2, SlotFilterEnabled: 0b}, {Disabled: 0b, IsEmptySlot: 1b, Slot: 3, SlotFilterEnabled: 0b}, {Disabled: 0b, IsEmptySlot: 1b, Slot: 4, SlotFilterEnabled: 0b}, {Disabled: 0b, IsEmptySlot: 1b, Slot: 5, SlotFilterEnabled: 0b}, {Disabled: 0b, IsEmptySlot: 1b, Slot: 6, SlotFilterEnabled: 0b}, {Disabled: 0b, IsEmptySlot: 1b, Slot: 7, SlotFilterEnabled: 0b}, {Disabled: 0b, IsEmptySlot: 1b, Slot: 8, SlotFilterEnabled: 0b}], Size: 9}, PoweredBefore: 0b, id: "anvilcraft:batch_crafter"}},
        {pos: [4, 0, 3], state: "anvilcraft:sliding_rail{axis:z}"},
        {pos: [4, 0, 4], state: "anvilcraft:sliding_rail_stop"},
        {pos: [0, 1, 4], state: "anvilcraft:charge_collector{powered:false}", nbt: {chargeCount: 0.0d, cooldownCount: 1, id: "anvilcraft:charge_collector", power: 0}},
        {pos: [1, 1, 3], state: "anvilcraft:active_silencer{powered:false}", nbt: {MutedSound: {mutedSound: []}, id: "anvilcraft:active_silencer"}},
        {pos: [2, 1, 2], state: "anvilcraft:chute{enabled:true,facing:down}", nbt: {Cooldown: 0, Inventory: {FilterEnabled: 0b, Inventory: [{Disabled: 0b, IsEmptySlot: 1b, Slot: 0, SlotFilterEnabled: 0b}, {Disabled: 0b, IsEmptySlot: 1b, Slot: 1, SlotFilterEnabled: 0b}, {Disabled: 0b, IsEmptySlot: 1b, Slot: 2, SlotFilterEnabled: 0b}, {Disabled: 0b, IsEmptySlot: 1b, Slot: 3, SlotFilterEnabled: 0b}, {Disabled: 0b, IsEmptySlot: 1b, Slot: 4, SlotFilterEnabled: 0b}, {Disabled: 0b, IsEmptySlot: 1b, Slot: 5, SlotFilterEnabled: 0b}, {Disabled: 0b, IsEmptySlot: 1b, Slot: 6, SlotFilterEnabled: 0b}, {Disabled: 0b, IsEmptySlot: 1b, Slot: 7, SlotFilterEnabled: 0b}, {Disabled: 0b, IsEmptySlot: 1b, Slot: 8, SlotFilterEnabled: 0b}], Size: 9}, id: "anvilcraft:chute"}},
        {pos: [4, 1, 0], state: "anvilcraft:transmission_pole{half:bottom,overload:true,switch:on}", nbt: {id: "anvilcraft:transmission_pole"}},
        {pos: [4, 1, 2], state: "anvilcraft:ember_grindstone{face:wall,facing:west}"},
        {pos: [4, 1, 3], state: "anvilcraft:royal_grindstone{face:wall,facing:west}"},
        {pos: [0, 2, 0], state: "anvilcraft:transcendence_anvil{facing:east}"},
        {pos: [1, 2, 0], state: "anvilcraft:ember_anvil{facing:east}"},
        {pos: [2, 2, 0], state: "anvilcraft:royal_anvil{facing:east}"},
        {pos: [3, 2, 0], state: "minecraft:anvil{facing:east}"},
        {pos: [4, 2, 0], state: "anvilcraft:transmission_pole{half:mid,overload:true,switch:on}", nbt: {id: "anvilcraft:transmission_pole"}},
        {pos: [4, 2, 2], state: "anvilcraft:ember_smithing_table"},
        {pos: [4, 2, 3], state: "anvilcraft:royal_smithing_table"},
        {pos: [0, 3, 0], state: "anvilcraft:magnet_block{lit:false}"},
        {pos: [0, 3, 1], state: "minecraft:lever{face:wall,facing:south,powered:false}"},
        {pos: [1, 3, 0], state: "anvilcraft:magnet_block{lit:false}"},
        {pos: [1, 3, 1], state: "minecraft:lever{face:wall,facing:south,powered:false}"},
        {pos: [2, 3, 0], state: "anvilcraft:magnet_block{lit:false}"},
        {pos: [2, 3, 1], state: "minecraft:lever{face:wall,facing:south,powered:false}"},
        {pos: [3, 3, 0], state: "anvilcraft:magnet_block{lit:false}"},
        {pos: [3, 3, 1], state: "minecraft:lever{face:wall,facing:south,powered:false}"},
        {pos: [4, 3, 0], state: "anvilcraft:transmission_pole{half:top,overload:false,switch:on}", nbt: {id: "anvilcraft:transmission_pole"}}
    ],
    entities: [],
    palette: [
        "anvilcraft:transparent_crafting_table{type:corner_nw}",
        "anvilcraft:transparent_crafting_table{type:side_w}",
        "anvilcraft:transparent_crafting_table{type:corner_sw}",
        "anvilcraft:transparent_crafting_table{type:side_n}",
        "anvilcraft:transparent_crafting_table{type:center}",
        "anvilcraft:transparent_crafting_table{type:side_s}",
        "anvilcraft:transparent_crafting_table{type:corner_ne}",
        "anvilcraft:transparent_crafting_table{type:side_e}",
        "anvilcraft:transparent_crafting_table{type:corner_se}",
        "anvilcraft:ember_smithing_table",
        "anvilcraft:royal_smithing_table",
        "anvilcraft:magnet_block{lit:false}",
        "anvilcraft:crushing_table{waterlogged:false}",
        "minecraft:cauldron",
        "anvilcraft:block_placer{orientation:south_up,triggered:false}",
        "anvilcraft:stamping_platform{facing:south,waterlogged:false}",
        "anvilcraft:sliding_rail{axis:z}",
        "anvilcraft:sliding_rail_stop",
        "anvilcraft:ember_grindstone{face:wall,facing:west}",
        "anvilcraft:royal_grindstone{face:wall,facing:west}",
        "anvilcraft:transcendence_anvil{facing:east}",
        "anvilcraft:ember_anvil{facing:east}",
        "anvilcraft:royal_anvil{facing:east}",
        "minecraft:anvil{facing:east}",
        "minecraft:lever{face:wall,facing:south,powered:false}",
        "anvilcraft:item_collector{overload:false,powered:false}",
        "anvilcraft:creative_generator",
        "anvilcraft:batch_crafter{facing:west,overload:false,powered:false}",
        "anvilcraft:charge_collector{powered:false}",
        "anvilcraft:active_silencer{powered:false}",
        "anvilcraft:chute{enabled:true,facing:down}",
        "anvilcraft:transmission_pole{half:bottom,overload:true,switch:on}",
        "anvilcraft:transmission_pole{half:mid,overload:true,switch:on}",
        "anvilcraft:transmission_pole{half:top,overload:false,switch:on}"
    ]
}